<?xml version="1.0" ?>
<robot xmlns:xacro="http://ros.org/wiki/xacro">

  <!-- left arm -->
  <xacro:macro name="social_robot_l_arm" params="parent">

  <!-- left shoulder pitch joint -->
  <joint name="LShoulder_Pitch" type="revolute">
    <origin
      xyz="0.1065 0.2815 0.00"
      rpy="0 ${-pi/2} ${-pi/2}" />
    <parent
      link="${parent}" />
    <child
      link="LShoulder_Pitch" />
    <axis
      xyz="0 1 0" />
    <limit
      effort="1000"
      velocity="100"
      lower="${-pi*0.9}"
      upper="${pi*0.9}" />
    <dynamics
      damping="0.1"
      friction="0.0" />
  </joint>
  <xacro:insert_transmission name="LShoulder_Pitch" />

  <!-- left shoulder pitch link -->
  <link name="LShoulder_Pitch">
    <inertial>
      <origin
        xyz="4.5422009E-04 4.3392074E-02 -5.2043389E-07"
        rpy="0 0 0" />
      <mass
        value="2.5106828E-01" />
      <inertia
        ixx="0"
        ixy="0"
        ixz="0"
        iyy="0"
        iyz="0"
        izz="0" />
    </inertial>
    <visual>
      <origin
        xyz="0 0 0"
        rpy="0 0 0" />
      <geometry>
        <mesh
          filename="package://social_robot_description/meshes/LShoulder_Pitch.stl" scale="0.001 0.001 0.001" />
      </geometry>
      <material
        name="">
        <color
          rgba="0.752941176470588 0.752941176470588 0.752941176470588 1" />
      </material>
    </visual>
    <collision>
      <origin
        xyz="0 0 0"
        rpy="0 0 0" />
      <geometry>
        <mesh
          filename="package://social_robot_description/meshes/LShoulder_Pitch.stl" scale="0.001 0.001 0.001" />
      </geometry>
    </collision>
  </link>

  <!-- left shoulder roll joint -->
  <joint name="LShoulder_Roll" type="revolute">
    <origin
      xyz="0 0.05975 0"
      rpy="0 0 0" />
    <parent
      link="LShoulder_Pitch" />
    <child
      link="LShoulder_Roll" />
    <axis
      xyz="1 0 0" />
    <limit
      effort="1000"
      velocity="100"
      lower="${-pi*0.9}"
      upper="${pi*0.9}" />
    <dynamics
      damping="0.1"
      friction="0.0" />
  </joint>
  <xacro:insert_transmission name="LShoulder_Roll" />

  <!-- left shoulder roll link -->
  <link name="LShoulder_Roll">
    <inertial>
      <origin
        xyz="-2.2708624E-05 6.8183465E-02 -1.3842578E-05"
        rpy="0 0 0" />
      <mass
        value="2.6316311E-01" />
      <inertia
        ixx="0"
        ixy="0"
        ixz="0"
        iyy="0"
        iyz="0"
        izz="0" />
    </inertial>
    <visual>
      <origin
        xyz="0 0 0"
        rpy="0 0 0" />
      <geometry>
        <mesh
          filename="package://social_robot_description/meshes/LShoulder_Roll.stl" scale="0.001 0.001 0.001" />
      </geometry>
      <material
        name="">
        <color
          rgba="0.752941176470588 0.752941176470588 0.752941176470588 1" />
      </material>
    </visual>
    <collision>
      <origin
        xyz="0 0 0"
        rpy="0 0 0" />
      <geometry>
        <mesh
          filename="package://social_robot_description/meshes/LShoulder_Roll.stl" scale="0.001 0.001 0.001" />
      </geometry>
    </collision>
  </link>

  <!-- left elbow pitch joint -->
  <joint name="LElbow_Pitch" type="revolute">
    <origin
      xyz="0 0.09525 0"
      rpy="0 0 0" />
    <parent
      link="LShoulder_Roll" />
    <child
      link="LElbow_Pitch" />
    <axis
      xyz="0 1 0" />
    <limit
      effort="1000"
      velocity="100"
      lower="${-pi*0.9}"
      upper="${pi*0.9}" />
    <dynamics
      damping="0.1"
      friction="0.0" />
  </joint>
  <xacro:insert_transmission name="LElbow_Pitch" />

  <!-- left elbow pitch link -->
  <link name="LElbow_Pitch">
    <inertial>
      <origin
        xyz="2.9928508E-07 6.7483293E-02 5.0643015E-04"
        rpy="0 0 0" />
      <mass
        value="2.2544242E-01" />
      <inertia
        ixx="0"
        ixy="0"
        ixz="0"
        iyy="0"
        iyz="0"
        izz="0" />
    </inertial>
    <visual>
      <origin
        xyz="0 0 0"
        rpy="0 0 0" />
      <geometry>
        <mesh
          filename="package://social_robot_description/meshes/LElbow_Pitch.stl" scale="0.001 0.001 0.001" />
      </geometry>
      <material
        name="">
        <color
          rgba="0.752941176470588 0.752941176470588 0.752941176470588 1" />
      </material>
    </visual>
    <collision>
      <origin
        xyz="0 0 0"
        rpy="0 0 0" />
      <geometry>
        <mesh
          filename="package://social_robot_description/meshes/LElbow_Pitch.stl" scale="0.001 0.001 0.001" />
      </geometry>
    </collision>
  </link>

  <!-- left elbow yaw joint -->
  <joint name="LElbow_Yaw" type="revolute">
    <origin
      xyz="0 0.086 0"
      rpy="0 0 0" />
    <parent
      link="LElbow_Pitch" />
    <child
      link="LElbow_Yaw" />
    <axis
      xyz="0 0 1" />
    <limit
      effort="1000"
      velocity="100"
      lower="${-pi*0.9}"
      upper="${pi*0.9}" />
    <dynamics
      damping="0.1"
      friction="0.0" />
  </joint>
  <xacro:insert_transmission name="LElbow_Yaw" />

  <!-- left elbow yaw -->
  <link name="LElbow_Yaw">
    <inertial>
      <origin
        xyz="-1.3358711E-04 5.8087493E-02 -9.6098218E-05"
        rpy="0 0 0" />
      <mass
        value="2.2625975E-01" />
      <inertia
        ixx="0"
        ixy="0"
        ixz="0"
        iyy="0"
        iyz="0"
        izz="0" />
    </inertial>
    <visual>
      <origin
        xyz="0 0 0"
        rpy="0 0 0" />
      <geometry>
        <mesh
          filename="package://social_robot_description/meshes/LElbow_Yaw.stl" scale="0.001 0.001 0.001" />
      </geometry>
      <material
        name="">
        <color
          rgba="0.752941176470588 0.752941176470588 0.752941176470588 1" />
      </material>
    </visual>
    <collision>
      <origin
        xyz="0 0 0"
        rpy="0 0 0" />
      <geometry>
        <mesh
          filename="package://social_robot_description/meshes/LElbow_Yaw.stl" scale="0.001 0.001 0.001" />
      </geometry>
    </collision>
  </link>

  <!-- left wrist pitch joint -->
  <joint name="LWrist_Pitch" type="revolute">
    <origin
      xyz="0 0.08745 0"
      rpy="0 0 0" />
    <parent
      link="LElbow_Yaw" />
    <child
      link="LWrist_Pitch" />
    <axis
      xyz="0 1 0" />
    <limit
      effort="1000"
      velocity="100"
      lower="${-pi*0.9}"
      upper="${pi*0.9}" />
    <dynamics
      damping="0.1"
      friction="0.0" />
  </joint>
  <xacro:insert_transmission name="LWrist_Pitch" />

  <!-- left wrist pitch link -->
  <link name="LWrist_Pitch">
    <inertial>
      <origin
        xyz="1.3880465E-03 6.4104565E-02 6.1201240E-03"
        rpy="0 0 0" />
      <mass
        value="2.6008606E-01" />
      <inertia
        ixx="0"
        ixy="0"
        ixz="0"
        iyy="0"
        iyz="0"
        izz="0" />
    </inertial>
    <visual>
      <origin
        xyz="0 0 0"
        rpy="0 0 0" />
      <geometry>
        <mesh
          filename="package://social_robot_description/meshes/LWrist_Pitch.stl" scale="0.001 0.001 0.001" />
      </geometry>
      <material
        name="">
        <color
          rgba="0.752941176470588 0.752941176470588 0.752941176470588 1" />
      </material>
    </visual>
    <collision>
      <origin
        xyz="0 0 0"
        rpy="0 0 0" />
      <geometry>
        <mesh
          filename="package://social_robot_description/meshes/LWrist_Pitch.stl" scale="0.001 0.001 0.001" />
      </geometry>
    </collision>
  </link>

  <!-- left finger joint -->
  <joint name="LFinger" type="revolute">
    <origin
      xyz="0.0212078 0.107735 0.0213208"
      rpy="0.01745329 0.104719755 -0.13962634" />
    <parent
      link="LWrist_Pitch" />
    <child
      link="LFinger" />
    <axis
      xyz="1 0 0" />
    <limit
      effort="1000"
      velocity="100"
      lower="${-pi*0.9}"
      upper="${pi*0.9}" />
    <dynamics
      damping="0.1"
      friction="0.0" />
  </joint>
  <xacro:insert_transmission name="LFinger" />

  <!-- left finger link -->
  <link name="LFinger">
    <inertial>
      <origin
        xyz="4.0198553E-03 2.8601502E-02 1.2028062E-06"
        rpy="0 0 0" />
      <mass
        value="8.1929027E-03" />
      <inertia
        ixx="0"
        ixy="0"
        ixz="0"
        iyy="0"
        iyz="0"
        izz="0" />
    </inertial>
    <visual>
      <origin
        xyz="0 0 0"
        rpy="-0.01745329 -0.104719755 0.13962634" />
      <geometry>
        <mesh
          filename="package://social_robot_description/meshes/LFinger.stl" scale="0.001 0.001 0.001" />
      </geometry>
      <material
        name="">
        <color
          rgba="0.752941176470588 0.752941176470588 0.752941176470588 1" />
      </material>
    </visual>
    <collision>
      <origin
        xyz="0 0 0"
        rpy="0 0 0" />
      <geometry>
        <mesh
          filename="package://social_robot_description/meshes/LFinger.stl" scale="0.001 0.001 0.001" />
      </geometry>
    </collision>
  </link>

  </xacro:macro>

</robot>
